Workbook

Sheet Curso Classif Desp.
A3: Orçamento Doméstico
D5: 43101 | F5: 43132 | H5: 43160 | J5: 43191 | L5: 43221 | N5: 43252 | P5: 43282 | R5: 43313 | T5: 43344 | V5: 43374 | X5: 43405 | Z5: 43435
A6: Receitas | C6: Descrição | D6: Orçado | E6: Realizado | F6: Orçado | G6: Realizado | H6: Orçado | I6: Realizado | J6: Orçado | K6: Realizado | L6: Orçado | M6: Realizado | N6: Orçado | O6: Realizado | P6: Orçado | Q6: Realizado | R6: Orçado | S6: Realizado | T6: Orçado | U6: Realizado | V6: Orçado | W6: Realizado | X6: Orçado | Y6: Realizado | Z6: Orçado | AA6: Realizado
C7: Salário | D7: 4000 | E7: 4000 | F7: 4000 | H7: 4000 | J7: 4000 | N7: 4000 | P7: 4000 | R7: 4000 | T7: 4000 | V7: 4000 | X7: 4000 | Z7: 4000
C8: Outros | D8: 0 | E8: 0 | F8: 0 | H8: 0 | J8: 0 | N8: 0 | P8: 0 | R8: 0 | T8: 0 | V8: 0 | X8: 0 | Z8: 0
C9: Horas extras | D9: 0 | E9: 100 | F9: 0 | H9: 0 | J9: 0 | N9: 0 | P9: 0 | R9: 0 | T9: 0 | V9: 0 | X9: 0 | Z9: 0
C10: 13º salário | D10: 0 | E10: 0 | F10: 0 | H10: 0 | J10: 0 | N10: 0 | P10: 0 | R10: 0 | T10: 0 | V10: 0 | X10: 0 | Z10: 0
C11: Férias | D11: 0 | E11: 0 | F11: 0 | H11: 0 | J11: 0 | N11: 0 | P11: 0 | R11: 0 | T11: 0 | V11: 0 | X11: 0 | Z11: 0
C12: Renda Extra | D12: 0 | E12: 0 | F12: 0 | H12: 0 | J12: 0 | L12: 0 | N12: 0 | P12: 0 | R12: 0 | T12: 0 | V12: 0 | X12: 0 | Z12: 0
C13: Total | D13: =SUM(D7:D12) -> 4000 | E13: =SUM(E7:E12) -> 4100 | F13: =SUM(F7:F12) -> 4000 | G13: =SUM(G7:G12) -> 0 | H13: =SUM(H7:H12) -> 4000 | I13: =SUM(I7:I12) -> 0 | J13: =SUM(J7:J12) -> 4000 | K13: =SUM(K7:K12) -> 0 | ... AA13: =SUM(AA7:AA12) -> 0
A15: Investimentos Insira aqui o montante mensal que você destinará aos seus investimentos | C15: Descrição | D15: Orçado | E15: Realizado | F15: Orçado | G15: Realizado | H15: Orçado | I15: Realizado | J15: Orçado | K15: Realizado | L15: Orçado | M15: Realizado | N15: Orçado | O15: Realizado | P15: Orçado | Q15: Realizado | R15: Orçado | S15: Realizado | T15: Orçado | U15: Realizado | V15: Orçado | W15: Realizado | X15: Orçado | Y15: Realizado | Z15: Orçado | AA15: Realizado
C16: Reserva de Emergência | D16: =D7*10% -> 400 | E16: =E13*10% -> 410 | F16: =F7*10% -> 400 | H16: =H7*10% -> 400 | J16: =J7*10% -> 400 | L16: =L7*10% -> 0 | N16: =N7*10% -> 400 | P16: =P7*10% -> 400 | R16: =R7*10% -> 400 | T16: =T7*10% -> 400 | V16: =V7*10% -> 400 | X16: =X7*10% -> 400 | Z16: =Z7*10% -> 400
C17: Plano de Aposentadoria | D17: 0 | E17: 0 | F17: 0 | H17: 0 | J17: 0 | L17: 0 | N17: 0 | P17: 0 | R17: 0 | T17: 0 | V17: 0 | X17: 0 | Z17: 0
C18: Independencia | D18: 0 | E18: 0 | F18: 0 | H18: 0 | J18: 0 | L18: 0 | N18: 0 | P18: 0 | R18: 0 | T18: 0 | V18: 0 | X18: 0 | Z18: 0
C19: Ações | D19: 0 | E19: 0 | F19: 0 | H19: 0 | J19: 0 | L19: 0 | N19: 0 | P19: 0 | R19: 0 | T19: 0 | V19: 0 | X19: 0 | Z19: 0
C20: Outros | D20: 0 | E20: 0 | F20: 0 | H20: 0 | J20: 0 | L20: 0 | N20: 0 | P20: 0 | R20: 0 | T20: 0 | V20: 0 | X20: 0 | Z20: 0
C22: Total | D22: =SUM(D16:D21) -> 400 | E22: =SUM(E16:E21) -> 410 | F22: =SUM(F16:F21) -> 400 | G22: =SUM(G16:G21) -> 0 | H22: =SUM(H16:H21) -> 400 | I22: =SUM(I16:I21) -> 0 | J22: =SUM(J16:J21) -> 400 | K22: =SUM(K16:K21) -> 0 | ... AA22: =SUM(AA16:AA21) -> 0
C23: % sobre Receita | D23: =D22/$D$13 -> 0.1 | E23: =E22/$D$13 -> 0.1025 | F23: =F22/$D$13 -> 0.1 | G23: =G22/$D$13 -> 0 | H23: =H22/$D$13 -> 0.1 | I23: =I22/$D$13 -> 0 | J23: =J22/$D$13 -> 0.1 | K23: =K22/$D$13 -> 0 | ... AA23: =AA22/$D$13 -> 0
A25: Categoria | C25: Despesa | D25: Orçado | E25: Realizado | F25: Orçado | G25: Realizado | H25: Orçado | I25: Realizado | J25: Orçado | K25: Realizado | L25: Orçado | M25: Realizado | N25: Orçado | O25: Realizado | P25: Orçado | Q25: Realizado | R25: Orçado | S25: Realizado | T25: Orçado | U25: Realizado | V25: Orçado | W25: Realizado | X25: Orçado | Y25: Realizado | Z25: Orçado | AA25: Realizado
A26: Fixas o mesmo montante mensalmente | B26: Habitação | C26: Prestação da casa | D26: 650 | E26: 650 | F26: 650 | H26: 650 | J26: 650 | N26: 650 | P26: 650 | R26: 650 | T26: 650 | V26: 650 | X26: 650 | Z26: 650
C27: Telefone | D27: 60 | E27: 50 | F27: 60 | H27: 60 | J27: 60 | N27: 60 | P27: 60 | R27: 60 | T27: 60 | V27: 60 | X27: 60 | Z27: 60
C28: Internet | D28: 80 | E28: 80 | F28: 80 | H28: 80 | J28: 80 | N28: 80 | P28: 80 | R28: 80 | T28: 80 | V28: 80 | X28: 80 | Z28: 80
D32: 80 | E32: 80 | F32: 80 | H32: 80 | J32: 80 | N32: 80 | P32: 80 | R32: 80 | T32: 80 | V32: 80 | X32: 80 | Z32: 80
B34: Transporte | C34: Prestação do carro | D34: 0 | E34: 0 | F34: 0 | H34: 0 | J34: 0 | N34: 0 | P34: 0 | R34: 0 | T34: 0 | V34: 0 | X34: 0 | Z34: 0
C35: Seguro do carro | D35: 60 | E35: 60 | F35: 60 | H35: 60 | J35: 60 | N35: 60 | P35: 60 | R35: 60 | T35: 60 | V35: 60 | X35: 60 | Z35: 60
B37: Saúde | C37: Academia | D37: 100 | E37: 100 | F37: 100 | H37: 100 | J37: 100 | N37: 100 | P37: 100 | R37: 100 | T37: 100 | V37: 100 | X37: 100 | Z37: 100
C38: Seguro de vida
C39: Plano de saúde
D41: 100 | E41: 100 | F41: 100 | H41: 100 | J41: 100 | N41: 100 | P41: 100 | R41: 100 | T41: 100 | V41: 100 | X41: 100 | Z41: 100
B43: Educação | C43: Livros | D43: 0 | E43: 0 | F43: 0 | H43: 0 | J43: 0 | N43: 0 | P43: 0 | R43: 0 | T43: 0 | V43: 0 | X43: 0 | Z43: 0
C44: Faculdade | D44: 0 | E44: 0 | F44: 0 | H44: 0 | J44: 0 | N44: 0 | P44: 0 | R44: 0 | T44: 0 | V44: 0 | X44: 0 | Z44: 0
D46: 0 | E46: 0 | F46: 0 | H46: 0 | J46: 0 | N46: 0 | P46: 0 | R46: 0 | T46: 0 | V46: 0 | X46: 0 | Z46: 0
B48: Impostos | C48: IPTU | D48: 50 | E48: 50 | F48: 50 | H48: 50 | J48: 50 | N48: 50 | P48: 50 | R48: 50 | T48: 50 | V48: 50 | X48: 50 | Z48: 50
C49: IPVA | D49: 0 | E49: 0 | F49: 0 | H49: 0 | J49: 0 | N49: 0 | P49: 0 | R49: 0 | T49: 0 | V49: 0 | X49: 0 | Z49: 0
D51: 0 | E51: 0 | F51: 0 | H51: 0 | J51: 0 | N51: 0 | P51: 0 | R51: 0 | T51: 0 | V51: 0 | X51: 0 | Z51: 0
B53: Espiritual | C53: Dízimo | D53: =$D$13*10% -> 400 | E53: 400 | F53: =$D$13*10% -> 400 | H53: =$D$13*10% -> 400 | J53: =$D$13*10% -> 400 | N53: =$D$13*10% -> 400 | P53: =$D$13*10% -> 400 | R53: =$D$13*10% -> 400 | T53: =$D$13*10% -> 400 | V53: =$D$13*10% -> 400 | X53: =$D$13*10% -> 400 | Z53: =$D$13*10% -> 400
C54: Ofertas | E54: 80
E55: 80
B57: Total despesas fixas | D57: =SUM(D26:D55) -> 1580 | E57: =SUM(E26:E55) -> 1730 | F57: =SUM(F26:F55) -> 1580 | G57: =SUM(G26:G55) -> 0 | H57: =SUM(H26:H55) -> 1580 | I57: =SUM(I26:I55) -> 0 | J57: =SUM(J26:J55) -> 1580 | K57: =SUM(K26:K55) -> 0 | ... AA57: =SUM(AA26:AA55) -> 0
B59: % sobre Receita | D59: =D57/$D$13 -> 0.395 | E59: =E57/$D$13 -> 0.4325 | F59: =F57/$D$13 -> 0.395 | G59: =G57/$D$13 -> 0 | H59: =H57/$D$13 -> 0.395 | I59: =I57/$D$13 -> 0 | J59: =J57/$D$13 -> 0.395 | K59: =K57/$D$13 -> 0 | N59: =N57/$D$13 -> 0.395 | O59: =O57/$D$13 -> 0 | P59: =P57/$D$13 -> 0.395 | Q59: =Q57/$D$13 -> 0 | R59: =R57/$D$13 -> 0.395 | S59: =S57/$D$13 -> 0 | T59: =T57/$D$13 -> 0.395 | U59: =U57/$D$13 -> 0 | ... AA59: =AA57/$D$13 -> 0
...

Sheet Mod. Controle de Gastos
A3: Controle de Gastos
D5: 43101 | F5: 43132 | H5: 43160 | J5: 43191 | L5: 43221 | N5: 43252 | P5: 43282 | R5: 43313 | T5: 43344 | V5: 43374 | X5: 43405 | Z5: 43435
A6: Receitas | C6: Descrição | D6: Orçado | E6: Realizado | F6: Orçado | G6: Realizado | H6: Orçado | I6: Realizado | J6: Orçado | K6: Realizado | L6: Orçado | M6: Realizado | N6: Orçado | O6: Realizado | P6: Orçado | Q6: Realizado | R6: Orçado | S6: Realizado | T6: Orçado | U6: Realizado | V6: Orçado | W6: Realizado | X6: Orçado | Y6: Realizado | Z6: Orçado | AA6: Realizado
C7: Salário | D7: 4000 | E7: 4000 | F7: 4000 | H7: 4000 | J7: 4000 | N7: 4000 | P7: 4000 | R7: 4000 | T7: 4000 | V7: 4000 | X7: 4000 | Z7: 4000
C8: Outros | D8: 0 | E8: 0 | F8: 0 | H8: 0 | J8: 0 | N8: 0 | P8: 0 | R8: 0 | T8: 0 | V8: 0 | X8: 0 | Z8: 0
C9: Horas extras | D9: 0 | E9: 100 | F9: 0 | H9: 0 | J9: 0 | N9: 0 | P9: 0 | R9: 0 | T9: 0 | V9: 0 | X9: 0 | Z9: 0
C10: 13º salário | D10: 0 | E10: 0 | F10: 0 | H10: 0 | J10: 0 | N10: 0 | P10: 0 | R10: 0 | T10: 0 | V10: 0 | X10: 0 | Z10: 0
C11: Férias | D11: 0 | E11: 0 | F11: 0 | H11: 0 | J11: 0 | N11: 0 | P11: 0 | R11: 0 | T11: 0 | V11: 0 | X11: 0 | Z11: 0
C12: Renda Extra | D12: 0 | E12: 0 | F12: 0 | H12: 0 | J12: 0 | L12: 0 | N12: 0 | P12: 0 | R12: 0 | T12: 0 | V12: 0 | X12: 0 | Z12: 0
C13: Total | D13: =SUM(D7:D12) -> 4000 | E13: =SUM(E7:E12) -> 4100 | F13: =SUM(F7:F12) -> 4000 | G13: =SUM(G7:G12) -> 0 | H13: =SUM(H7:H12) -> 4000 | I13: =SUM(I7:I12) -> 0 | J13: =SUM(J7:J12) -> 4000 | K13: =SUM(K7:K12) -> 0 | ... AA13: =SUM(AA7:AA12) -> 0
A15: Investimentos Insira aqui o montante mensal que você destinará aos seus investimentos | C15: Descrição | D15: Orçado | E15: Realizado | F15: Orçado | G15: Realizado | H15: Orçado | I15: Realizado | J15: Orçado | K15: Realizado | L15: Orçado | M15: Realizado | N15: Orçado | O15: Realizado | P15: Orçado | Q15: Realizado | R15: Orçado | S15: Realizado | T15: Orçado | U15: Realizado | V15: Orçado | W15: Realizado | X15: Orçado | Y15: Realizado | Z15: Orçado | AA15: Realizado
C16: Reserva de Emergência | D16: =D7*10% -> 400 | E16: =E13*10% -> 410 | F16: =F7*10% -> 400 | H16: =H7*10% -> 400 | J16: =J7*10% -> 400 | L16: =L7*10% -> 0 | N16: =N7*10% -> 400 | P16: =P7*10% -> 400 | R16: =R7*10% -> 400 | T16: =T7*10% -> 400 | V16: =V7*10% -> 400 | X16: =X7*10% -> 400 | Z16: =Z7*10% -> 400
C17: Plano de Aposentadoria | D17: 0 | E17: 0 | F17: 0 | H17: 0 | J17: 0 | L17: 0 | N17: 0 | P17: 0 | R17: 0 | T17: 0 | V17: 0 | X17: 0 | Z17: 0
C18: Independencia | D18: 0 | E18: 0 | F18: 0 | H18: 0 | J18: 0 | L18: 0 | N18: 0 | P18: 0 | R18: 0 | T18: 0 | V18: 0 | X18: 0 | Z18: 0
C19: Ações | D19: 0 | E19: 0 | F19: 0 | H19: 0 | J19: 0 | L19: 0 | N19: 0 | P19: 0 | R19: 0 | T19: 0 | V19: 0 | X19: 0 | Z19: 0
C20: Outros | D20: 0 | E20: 0 | F20: 0 | H20: 0 | J20: 0 | L20: 0 | N20: 0 | P20: 0 | R20: 0 | T20: 0 | V20: 0 | X20: 0 | Z20: 0
C22: Total | D22: =SUM(D16:D21) -> 400 | E22: =SUM(E16:E21) -> 410 | F22: =SUM(F16:F21) -> 400 | G22: =SUM(G16:G21) -> 0 | H22: =SUM(H16:H21) -> 400 | I22: =SUM(I16:I21) -> 0 | J22: =SUM(J16:J21) -> 400 | K22: =SUM(K16:K21) -> 0 | ... AA22: =SUM(AA16:AA21) -> 0
C23: % sobre Receita | D23: =D22/$D$13 -> 0.1 | E23: =E22/$D$13 -> 0.1025 | F23: =F22/$D$13 -> 0.1 | G23: =G22/$D$13 -> 0 | H23: =H22/$D$13 -> 0.1 | I23: =I22/$D$13 -> 0 | J23: =J22/$D$13 -> 0.1 | K23: =K22/$D$13 -> 0 | ... AA23: =AA22/$D$13 -> 0
A25: Categoria | C25: Despesa | D25: Orçado | E25: Realizado | F25: Orçado | G25: Realizado | H25: Orçado | I25: Realizado | J25: Orçado | K25: Realizado | L25: Orçado | M25: Realizado | N25: Orçado | O25: Realizado | P25: Orçado | Q25: Realizado | R25: Orçado | S25: Realizado | T25: Orçado | U25: Realizado | V25: Orçado | W25: Realizado | X25: Orçado | Y25: Realizado | Z25: Orçado | AA25: Realizado
A26: Fixas o mesmo montante mensalmente | B26: Habitação | C26: Prestação / Aluguel | D26: 650 | E26: 650 | F26: 650 | H26: 650 | J26: 650 | N26: 650 | P26: 650 | R26: 650 | T26: 650 | V26: 650 | X26: 650 | Z26: 650
C27: Telefone | D27: 60 | E27: 50 | F27: 60 | H27: 60 | J27: 60 | N27: 60 | P27: 60 | R27: 60 | T27: 60 | V27: 60 | X27: 60 | Z27: 60
C28: Internet | D28: 80 | E28: 80 | F28: 80 | H28: 80 | J28: 80 | N28: 80 | P28: 80 | R28: 80 | T28: 80 | V28: 80 | X28: 80 | Z28: 80
D32: 80 | E32: 80 | F32: 80 | H32: 80 | J32: 80 | N32: 80 | P32: 80 | R32: 80 | T32: 80 | V32: 80 | X32: 80 | Z32: 80
B34: Transporte | C34: Prestação do carro | D34: 0 | E34: 0 | F34: 0 | H34: 0 | J34: 0 | N34: 0 | P34: 0 | R34: 0 | T34: 0 | V34: 0 | X34: 0 | Z34: 0
C35: Seguro do carro | D35: 60 | E35: 60 | F35: 60 | H35: 60 | J35: 60 | N35: 60 | P35: 60 | R35: 60 | T35: 60 | V35: 60 | X35: 60 | Z35: 60
B37: Saúde | C37: Academia | D37: 100 | E37: 100 | F37: 100 | H37: 100 | J37: 100 | N37: 100 | P37: 100 | R37: 100 | T37: 100 | V37: 100 | X37: 100 | Z37: 100
C38: Seguro de vida
C39: Plano de saúde
D41: 100 | E41: 100 | F41: 100 | H41: 100 | J41: 100 | N41: 100 | P41: 100 | R41: 100 | T41: 100 | V41: 100 | X41: 100 | Z41: 100
B43: Educação | C43: Livros | D43: 0 | E43: 0 | F43: 0 | H43: 0 | J43: 0 | N43: 0 | P43: 0 | R43: 0 | T43: 0 | V43: 0 | X43: 0 | Z43: 0
C44: Faculdade | D44: 0 | E44: 0 | F44: 0 | H44: 0 | J44: 0 | N44: 0 | P44: 0 | R44: 0 | T44: 0 | V44: 0 | X44: 0 | Z44: 0
D46: 0 | E46: 0 | F46: 0 | H46: 0 | J46: 0 | N46: 0 | P46: 0 | R46: 0 | T46: 0 | V46: 0 | X46: 0 | Z46: 0
B48: Impostos | C48: IPTU | D48: 50 | E48: 50 | F48: 50 | H48: 50 | J48: 50 | N48: 50 | P48: 50 | R48: 50 | T48: 50 | V48: 50 | X48: 50 | Z48: 50
C49: IPVA | D49: 0 | E49: 0 | F49: 0 | H49: 0 | J49: 0 | N49: 0 | P49: 0 | R49: 0 | T49: 0 | V49: 0 | X49: 0 | Z49: 0
C50: INSS
C51: IRRF | D51: 0 | E51: 0 | F51: 0 | H51: 0 | J51: 0 | N51: 0 | P51: 0 | R51: 0 | T51: 0 | V51: 0 | X51: 0 | Z51: 0
B53: Espiritual | C53: Dízimo | D53: =$D$13*10% -> 400 | E53: 400 | F53: =$D$13*10% -> 400 | H53: =$D$13*10% -> 400 | J53: =$D$13*10% -> 400 | N53: =$D$13*10% -> 400 | P53: =$D$13*10% -> 400 | R53: =$D$13*10% -> 400 | T53: =$D$13*10% -> 400 | V53: =$D$13*10% -> 400 | X53: =$D$13*10% -> 400 | Z53: =$D$13*10% -> 400
C54: Ofertas | E54: 80
E55: 80
B57: Total despesas fixas | D57: =SUM(D26:D55) -> 1580 | E57: =SUM(E26:E55) -> 1730 | F57: =SUM(F26:F55) -> 1580 | G57: =SUM(G26:G55) -> 0 | H57: =SUM(H26:H55) -> 1580 | I57: =SUM(I26:I55) -> 0 | J57: =SUM(J26:J55) -> 1580 | K57: =SUM(K26:K55) -> 0 | ... AA57: =SUM(AA26:AA55) -> 0
...

Sheet Mod. Orçamento Doméstico
A3: Orçamento Doméstico | P3: Orçamento Doméstico
A5: Categoria | C5: Descrição | D5: 43101 | F5: 43132 | H5: 43160 | J5: 43191 | L5: 43221 | N5: 43252 | S5: 43282 | U5: 43313 | W5: 43344 | Y5: 43374 | AA5: 43405 | AC5: 43435
D6: Orçado | E6: Realizado | F6: Orçado | G6: Realizado | H6: Orçado | I6: Realizado | J6: Orçado | K6: Realizado | L6: Orçado | M6: Realizado | N6: Orçado | O6: Realizado | R6: Descrição | S6: Orçado | T6: Realizado | U6: Orçado | V6: Realizado | W6: Orçado | X6: Realizado | Y6: Orçado | Z6: Realizado | AA6: Orçado | AB6: Realizado | AC6: Orçado | AD6: Realizado
A7: Receitas | C7: Salário | P7: Receitas | R7: Salário
C8: Outros | R8: Outros
C9: Horas extras | R9: Horas extras
C10: 13º salário | R10: 13º salário
C11: Férias | R11: Férias
C12: Renda Extra | R12: Renda Extra
C13: Total | R13: Total
A15: Investimentos Insira aqui o montante mensal que você destinará aos seus investimentos | C15: Descrição | D15: Orçado | E15: Realizado | F15: Orçado | G15: Realizado | H15: Orçado | I15: Realizado | J15: Orçado | K15: Realizado | L15: Orçado | M15: Realizado | N15: Orçado | O15: Realizado | P15: Investimentos Insira aqui o montante mensal que você destinará aos seus investimentos | R15: Descrição | S15: Orçado | T15: Realizado | U15: Orçado | V15: Realizado | W15: Orçado | X15: Realizado | Y15: Orçado | Z15: Realizado | AA15: Orçado | AB15: Realizado | AC15: Orçado | AD15: Realizado
C16: Reserva de Emergência | D16: =D7*10% -> 0 | E16: =E13*10% -> 0 | F16: =F7*10% -> 0 | H16: =H7*10% -> 0 | J16: =J7*10% -> 0 | L16: =L7*10% -> 0 | N16: =N7*10% -> 0 | R16: Reserva de Emergência | S16: =S7*10% -> 0 | U16: =U7*10% -> 0 | W16: =W7*10% -> 0 | Y16: =Y7*10% -> 0 | AA16: =AA7*10% -> 0 | AC16: =AC7*10% -> 0
C17: Plano de Aposentadoria | D17: 0 | E17: 0 | F17: 0 | H17: 0 | J17: 0 | L17: 0 | N17: 0 | R17: Plano de Aposentadoria | S17: 0 | U17: 0 | W17: 0 | Y17: 0 | AA17: 0 | AC17: 0
C18: Independencia | D18: 0 | E18: 0 | F18: 0 | H18: 0 | J18: 0 | L18: 0 | N18: 0 | R18: Independencia | S18: 0 | U18: 0 | W18: 0 | Y18: 0 | AA18: 0 | AC18: 0
C19: Ações | D19: 0 | E19: 0 | F19: 0 | H19: 0 | J19: 0 | L19: 0 | N19: 0 | R19: Ações | S19: 0 | U19: 0 | W19: 0 | Y19: 0 | AA19: 0 | AC19: 0
C20: Outros | D20: 0 | E20: 0 | F20: 0 | H20: 0 | J20: 0 | L20: 0 | N20: 0 | R20: Outros | S20: 0 | U20: 0 | W20: 0 | Y20: 0 | AA20: 0 | AC20: 0
C22: Total | D22: =SUM(D16:D21) -> 0 | E22: =SUM(E16:E21) -> 0 | F22: =SUM(F16:F21) -> 0 | G22: =SUM(G16:G21) -> 0 | H22: =SUM(H16:H21) -> 0 | I22: =SUM(I16:I21) -> 0 | J22: =SUM(J16:J21) -> 0 | K22: =SUM(K16:K21) -> 0 | ... O22: =SUM(O16:O21) -> 0 | R22: Total | S22: =SUM(S16:S21) -> 0 | T22: =SUM(T16:T21) -> 0 | U22: =SUM(U16:U21) -> 0 | V22: =SUM(V16:V21) -> 0 | W22: =SUM(W16:W21) -> 0 | X22: =SUM(X16:X21) -> 0 | Y22: =SUM(Y16:Y21) -> 0 | Z22: =SUM(Z16:Z21) -> 0 | ... AD22: =SUM(AD16:AD21) -> 0
C23: % sobre Receita | D23: =D22/$D$13 -> #DIV/0! | E23: =E22/$D$13 -> #DIV/0! | F23: =F22/$D$13 -> #DIV/0! | G23: =G22/$D$13 -> #DIV/0! | H23: =H22/$D$13 -> #DIV/0! | I23: =I22/$D$13 -> #DIV/0! | J23: =J22/$D$13 -> #DIV/0! | K23: =K22/$D$13 -> #DIV/0! | ... O23: =O22/$D$13 -> #DIV/0! | R23: % sobre Receita | S23: =S22/$D$13 -> #DIV/0! | T23: =T22/$D$13 -> #DIV/0! | U23: =U22/$D$13 -> #DIV/0! | V23: =V22/$D$13 -> #DIV/0! | W23: =W22/$D$13 -> #DIV/0! | X23: =X22/$D$13 -> #DIV/0! | Y23: =Y22/$D$13 -> #DIV/0! | Z23: =Z22/$D$13 -> #DIV/0! | ... AD23: =AD22/$D$13 -> #DIV/0!
A25: Categoria | C25: Descrição | D25: Orçado | E25: Realizado | F25: Orçado | G25: Realizado | H25: Orçado | I25: Realizado | J25: Orçado | K25: Realizado | L25: Orçado | M25: Realizado | N25: Orçado | O25: Realizado | P25: Descrição | R25: Descrição | S25: Orçado | T25: Realizado | U25: Orçado | V25: Realizado | W25: Orçado | X25: Realizado | Y25: Orçado | Z25: Realizado | AA25: Orçado | AB25: Realizado | AC25: Orçado | AD25: Realizado
A26: Fixas o mesmo montante mensalmente | B26: Habitação | C26: Prestação / Aluguel | P26: Fixas o mesmo montante mensalmente | Q26: Habitação | R26: Prestação / Aluguel
C27: Telefone | R27: Telefone
C28: Internet | R28: Internet
B34: Transporte | C34: Prestação do carro | Q34: Transporte | R34: Prestação do carro
C35: Seguro do carro | R35: Seguro do carro
B37: Saúde | C37: Academia | Q37: Saúde | R37: Academia
C38: Seguro de vida | R38: Seguro de vida
C39: Plano de saúde | R39: Plano de saúde
B43: Educação | C43: Livros | Q43: Educação | R43: Livros
C44: Faculdade | R44: Faculdade
B48: Impostos | C48: IPTU | Q48: Impostos | R48: IPTU
C49: IPVA | R49: IPVA
C50: INSS
C51: IRRF
B53: Espiritual | C53: Dízimo | Q53: Espiritual | R53: Dízimo
C54: Ofertas | R54: Ofertas
B57: Total despesas fixas | Q57: Total despesas fixas
B59: % sobre Receita | Q59: % sobre Receita
A61: Variáveis aquelas que acontecem mensalmente, mas podemos tentar reduzir | B61: Moradia | C61: Luz | P61: Variáveis aquelas que acontecem mensalmente, mas podemos tentar reduzir | Q61: Moradia | R61: Luz
C62: Água | R62: Água
C63: Telefone Celular | R63: Telefone Celular
...

Sheet Controle de Gastos
B2: CONTROLE DE GASTOS
B4: SALDO ANTERIOR
B6: GANHOS | F6: GASTOS | L6: Cartão de Crédito
B7: Data | C7: Fonte | D7: Valor | F7: Data | G7: Descrição | H7: Valor | I7: Parcela | J7: Class. | L7: Descrição | M7: Valor | N7: Parcela | O7: Class.
B31: TOTAL | D31: =SUM(D8:D30) -> 0
B33: SALDO INICIAL | D33: =D4+D31 -> 0
B35: INVESTIMENTOS
B36: Data | C36: Tipo | D36: Valor
G41: Cartão de Crédito | H41: =M43 -> 0
B43: TOTAL | D43: =SUM(D37:D42) -> 0 | F43: TOTAL | H43: =SUM(H8:H42) -> 0 | L43: TOTAL | M43: =SUM(M8:M42) -> 0
B45: LEGENDA: Classificação das Despesas | F45: SALDO FINAL | H45: =D33-D43-H43 -> 0 | L45: Endividamento
B46: Fixos Prioritários (FP): o mesmo montante mensalmente, extremamente necessários | L46: Valor das Parcelas
B47: Variáveis Prioritários (VP): não acontecem mensalmente, são extremamente necessários, alguns podem ser reduzidos | L47: Receita Fixa
B48: Fixos Secundários (FS): o mesmo montante mensalmente, mas podem ser reduzidos | L48: Índice de Endividamento | M48: =M46/M47 -> #DIV/0!
B49: Variáveis Secundários (VS): não precisam, necessariamente acontecer.

Sheet Instruções para preenchimento
A1: Instruções para Preenchimento
A2: Orçamento Familiar | B2: - As descrições devem ser alteradas somente na aba "Orçamento Familiar", ela irá reproduzir, automaticamente, nas outras abas. - Para definir o valor que será poupado, mensalmente, para a reserva de emergência, pode-se somente alterar o percentual na célula "D19". Se preferir, também pode desconsiderar o percentual e colocar o valor fixo para cada mês - Inserir os valores esperados mensais para cada subcategoria - Verificar o saldo final (buscar sempre deixar o saldo positivo)
A3: Meses | B3: - Toda alteração de descrição deve ser feita na aba "Orçamento Familiar" - Sugestão atualizar os lançamentos das despesas, semanalmente, para melhor controle - Verificar o saldo final (buscar sempre deixar o saldo positivo)
A4: Fluxo de Caixa | B4: - Traz o resumo das receitas e despesas "Orçado x Realizado" mensais e anual, portanto deve ser utilizada para avaliação, não precisa preencher nada

Sheet Orçamento Familiar
A3: Orçamento Familiar
A5: Categoria | C5: Descrição | D5: Percentual | E5: 46023 | F5: 46054 | G5: 46082 | H5: 46113 | I5: 46143 | J5: 46174 | K5: 46204 | L5: 46235 | M5: 46266 | N5: 46296 | O5: 46327 | P5: 46357 | Q5: Total
A7: Receitas | C7: Prebenda | E7: 7216 | F7: 7216 | G7: 7216 | H7: 7216 | I7: 7216 | J7: 7216 | K7: 7216 | L7: 7216 | M7: 7216 | N7: 7216 | O7: 7216 | P7: 7216 | Q7: =SUM(E7:P7) -> 86592
C8: Inglês | E8: 340 | F8: 340 | G8: 335 | H8: 335 | I8: 335 | J8: 335 | K8: 335 | L8: 335 | M8: 335 | N8: 335 | O8: 335 | P8: 335 | Q8: =SUM(E8:P8) -> 4030
C9: 13º Salário | O9: =O7/2 -> 3608 | P9: =P7/2 -> 3608 | Q9: =SUM(E9:P9) -> 7216
C10: Renda Extra | Q10: =SUM(E10:P10) -> 0
Q11: =SUM(E11:P11) -> 0
Q12: =SUM(E12:P12) -> 0
Q13: =SUM(E13:P13) -> 0
Q14: =SUM(E14:P14) -> 0
Q15: =SUM(E15:P15) -> 0
C16: Total | E16: =SUM(E7:E15) -> 7556 | F16: =SUM(F7:F15) -> 7556 | G16: =SUM(G7:G15) -> 7551 | H16: =SUM(H7:H15) -> 7551 | I16: =SUM(I7:I15) -> 7551 | J16: =SUM(J7:J15) -> 7551 | K16: =SUM(K7:K15) -> 7551 | L16: =SUM(L7:L15) -> 7551 | ... Q16: =SUM(Q7:Q15) -> 97838
A18: Investimentos Insira aqui o montante mensal que você destinará aos seus investimentos | C18: Descrição | D18: Percentual | E18: =E5 -> 46023 | F18: =F5 -> 46054 | G18: =G5 -> 46082 | H18: =H5 -> 46113 | I18: =I5 -> 46143 | J18: =J5 -> 46174 | K18: =K5 -> 46204 | L18: =L5 -> 46235 | ... Q18: =Q5 -> Total
C19: Reserva de Emergência (CP) R$ 9.151 | E19: =E16*$D$19 -> 0 | F19: =F16*$D$19 -> 0 | G19: =G16*$D$19 -> 0 | H19: =H16*$D$19 -> 0 | I19: =I16*$D$19 -> 0 | J19: =J16*$D$19 -> 0 | K19: =K16*$D$19 -> 0 | L19: =L16*$D$19 -> 0 | ... P19: =P16*$D$19 -> 0 | Q19: =SUM(E19:P19) -> 0
C20: Projeto 1 | Q20: =SUM(E20:P20) -> 0
C21: Projeto 2 | Q21: =SUM(E21:P21) -> 0
C22: Projeto 3 | Q22: =SUM(E22:P22) -> 0
C23: Projeto 4 | Q23: =SUM(E23:P23) -> 0
C24: Projeto 5 | Q24: =SUM(E24:P24) -> 0
C25: Projeto 6 | Q25: =SUM(E25:P25) -> 0
C26: Independência Financeira | Q26: =SUM(E26:P26) -> 0
C27: Total Investimentos | E27: =SUM(E19:E26) -> 0 | F27: =SUM(F19:F26) -> 0 | G27: =SUM(G19:G26) -> 0 | H27: =SUM(H19:H26) -> 0 | I27: =SUM(I19:I26) -> 0 | J27: =SUM(J19:J26) -> 0 | K27: =SUM(K19:K26) -> 0 | L27: =SUM(L19:L26) -> 0 | ... Q27: =SUM(Q19:Q26) -> 0
C28: % sobre Receita | E28: =E27/E16 -> 0 | F28: =F27/F16 -> 0 | G28: =G27/G16 -> 0 | H28: =H27/H16 -> 0 | I28: =I27/I16 -> 0 | J28: =J27/J16 -> 0 | K28: =K27/K16 -> 0 | L28: =L27/L16 -> 0 | ... Q28: =Q27/Q16 -> 0
A30: Categoria | C30: Descrição | E30: =E5 -> 46023 | F30: =F5 -> 46054 | G30: =G5 -> 46082 | H30: =H5 -> 46113 | I30: =I5 -> 46143 | J30: =J5 -> 46174 | K30: =K5 -> 46204 | L30: =L5 -> 46235 | ... Q30: =Q5 -> Total
A31: Despesas Essenciais | B31: Moradia | C31: Aluguel | Q31: =SUM(E31:P31) -> 0
C32: Energia Elétrica | Q32: =SUM(E32:P32) -> 0
C33: Água e Esgoto | Q33: =SUM(E33:P33) -> 0
C34: Gás | Q34: =SUM(E34:P34) -> 0
C35: Internet e Celular | E35: 125 | F35: 125 | G35: 184.7 | H35: 184.7 | I35: 184.7 | J35: 184.7 | K35: 184.7 | L35: 184.7 | M35: 184.7 | N35: 184.7 | O35: 184.7 | P35: 184.7 | Q35: =SUM(E35:P35) -> 2097
C36: Manutenção | G36: 50 | H36: 50 | I36: 50 | J36: 50 | K36: 50 | L36: 50 | M36: 50 | N36: 50 | O36: 50 | P36: 50 | Q36: =SUM(E36:P36) -> 500
Q37: =SUM(E37:P37) -> 0
Q38: =SUM(E38:P38) -> 0
Q39: =SUM(E39:P39) -> 0
B40: Alimentação | C40: Supermercado | E40: 3100 | F40: 3100 | G40: 3100 | H40: 3100 | I40: 3100 | J40: 3100 | K40: 3100 | L40: 3100 | M40: 3100 | N40: 3100 | O40: 3100 | P40: 3100 | Q40: =SUM(E40:P40) -> 37200
Q41: =SUM(E41:P41) -> 0
Q42: =SUM(E42:P42) -> 0
Q43: =SUM(E43:P43) -> 0
Q44: =SUM(E44:P44) -> 0
Q45: =SUM(E45:P45) -> 0
B46: Transporte | C46: Combustível | E46: 400 | F46: 400 | G46: 400 | H46: 400 | I46: 400 | J46: 400 | K46: 400 | L46: 400 | M46: 400 | N46: 400 | O46: 400 | P46: 400 | Q46: =SUM(E46:P46) -> 4800
...

Sheet Jan
A2: Fluxo de Caixa Familiar
A5: Categoria | C5: Descrição | D5: Percentual | E5: =I5 -> Janeiro | I5: Janeiro
E6: Orçado | F6: Realizado | G6: Variação | I6: Semana 1 | J6: Semana 2 | K6: Semana 3 | L6: Semana 4 | M6: Semana 5 | N6: Cartão Nubank | O6: Cartão C & A | P6: Total
A7: Receitas | C7: ='Orçamento Familiar'!C7 -> Prebenda | E7: ='Orçamento Familiar'!E7 -> 7216 | F7: =P7 -> 6296 | G7: =F7-E7 -> -920 | I7: 6296 | P7: =SUM(I7:O7) -> 6296
C8: ='Orçamento Familiar'!C8 -> Inglês | E8: ='Orçamento Familiar'!E8 -> 340 | F8: =P8 -> 335 | G8: =F8-E8 -> -5 | I8: 200 | K8: 135 | P8: =SUM(I8:O8) -> 335
C9: ='Orçamento Familiar'!C9 -> 13º Salário | E9: ='Orçamento Familiar'!E9 -> 0 | F9: =P9 -> 0 | G9: =F9-E9 -> 0 | P9: =SUM(I9:O9) -> 0
C10: ='Orçamento Familiar'!C10 -> Renda Extra | E10: ='Orçamento Familiar'!E10 -> 0 | F10: =P10 -> 1880 | G10: =F10-E10 -> 1880 | I10: 240 | K10: 1500 | L10: 140 | P10: =SUM(I10:O10) -> 1880 | Q10: 1500,00- vale + 240,00 Eric + 140,00 Levi
C11: ='Orçamento Familiar'!C11 -> 0 | E11: ='Orçamento Familiar'!E11 -> 0 | F11: =P11 -> 290 | G11: =F11-E11 -> 290 | K11: 290 | P11: =SUM(I11:O11) -> 290
C12: ='Orçamento Familiar'!C12 -> 0 | E12: ='Orçamento Familiar'!E12 -> 0 | F12: =P12 -> 0 | G12: =F12-E12 -> 0 | P12: =SUM(I12:O12) -> 0
C13: ='Orçamento Familiar'!C13 -> 0 | E13: ='Orçamento Familiar'!E13 -> 0 | F13: =P13 -> 0 | G13: =F13-E13 -> 0 | P13: =SUM(I13:O13) -> 0
C14: ='Orçamento Familiar'!C14 -> 0 | E14: ='Orçamento Familiar'!E14 -> 0 | F14: =P14 -> 0 | G14: =F14-E14 -> 0 | P14: =SUM(I14:O14) -> 0
C15: ='Orçamento Familiar'!C15 -> 0 | E15: ='Orçamento Familiar'!E15 -> 0 | F15: =P15 -> 0 | G15: =F15-E15 -> 0 | P15: =SUM(I15:O15) -> 0
C16: Total | E16: =SUM(E7:E15) -> 7556 | F16: =SUM(F7:F15) -> 8801 | G16: =SUM(G7:G15) -> 1245 | I16: =SUM(I7:I15) -> 6736 | J16: =SUM(J7:J15) -> 0 | K16: =SUM(K7:K15) -> 1925 | L16: =SUM(L7:L15) -> 140 | M16: =SUM(M7:M15) -> 0 | N16: =SUM(N7:N15) -> 0 | O16: =SUM(O7:O15) -> 0 | P16: =SUM(P7:P15) -> 8801
A18: Investimentos Insira aqui o montante mensal que você destinará aos seus investimentos | C18: Descrição | D18: Percentual | E18: Orçado | F18: Realizado | G18: Variação | I18: =I6 -> Semana 1 | J18: =J6 -> Semana 2 | K18: =K6 -> Semana 3 | L18: =L6 -> Semana 4 | M18: =M6 -> Semana 5 | P18: =P6 -> Total
C19: ='Orçamento Familiar'!C19 -> Reserva de Emergência (CP) R$ 9.151 | E19: ='Orçamento Familiar'!E19 -> 0 | F19: =P19 -> 0 | G19: =F19-E19 -> 0 | P19: =SUM(I19:O19) -> 0
C20: ='Orçamento Familiar'!C20 -> Projeto 1 | E20: ='Orçamento Familiar'!E20 -> 0 | F20: =P20 -> 0 | G20: =F20-E20 -> 0 | P20: =SUM(I20:O20) -> 0
C21: ='Orçamento Familiar'!C21 -> Projeto 2 | E21: ='Orçamento Familiar'!E21 -> 0 | F21: =P21 -> 0 | G21: =F21-E21 -> 0 | P21: =SUM(I21:O21) -> 0
C22: ='Orçamento Familiar'!C22 -> Projeto 3 | E22: ='Orçamento Familiar'!E22 -> 0 | F22: =P22 -> 0 | G22: =F22-E22 -> 0 | P22: =SUM(I22:O22) -> 0
C23: ='Orçamento Familiar'!C23 -> Projeto 4 | E23: ='Orçamento Familiar'!E23 -> 0 | F23: =P23 -> 0 | G23: =F23-E23 -> 0 | P23: =SUM(I23:O23) -> 0
C24: ='Orçamento Familiar'!C24 -> Projeto 5 | E24: ='Orçamento Familiar'!E24 -> 0 | F24: =P24 -> 0 | G24: =F24-E24 -> 0 | P24: =SUM(I24:O24) -> 0
C25: ='Orçamento Familiar'!C25 -> Projeto 6 | E25: ='Orçamento Familiar'!E25 -> 0 | F25: =P25 -> 0 | G25: =F25-E25 -> 0 | P25: =SUM(I25:O25) -> 0
C26: ='Orçamento Familiar'!C26 -> Independência Financeira | E26: ='Orçamento Familiar'!E26 -> 0 | F26: =P26 -> 0 | G26: =F26-E26 -> 0 | P26: =SUM(I26:O26) -> 0
C27: Total Investimentos | D27: =SUM(D19:D26) -> 0 | E27: =SUM(E19:E26) -> 0 | F27: =SUM(F19:F26) -> 0 | G27: =SUM(G19:G26) -> 0 | I27: =SUM(I19:I26) -> 0 | J27: =SUM(J19:J26) -> 0 | K27: =SUM(K19:K26) -> 0 | L27: =SUM(L19:L26) -> 0 | M27: =SUM(M19:M26) -> 0 | N27: =SUM(N19:N26) -> 0 | O27: =SUM(O19:O26) -> 0 | P27: =SUM(P19:P26) -> 0
C28: % sobre Receita | E28: =E27/E16 -> 0 | F28: =F27/F16 -> 0 | I28: =I27/I16 -> 0 | J28: =J27/J16 -> #DIV/0! | K28: =K27/K16 -> 0 | L28: =L27/L16 -> 0 | M28: =M27/M16 -> #DIV/0! | N28: =N27/N16 -> #DIV/0! | O28: =O27/O16 -> #DIV/0! | P28: =P27/P16 -> 0
A30: Categoria | C30: Descrição | D30: Percentual | E30: Orçado | F30: Realizado | G30: Variação | I30: =I18 -> Semana 1 | J30: =J18 -> Semana 2 | K30: =K18 -> Semana 3 | L30: =L18 -> Semana 4 | M30: =M18 -> Semana 5 | N30: =N6 -> Cartão Nubank | O30: =O6 -> Cartão C & A | P30: =P18 -> Total
A31: Despesas Essenciais | B31: Moradia | C31: ='Orçamento Familiar'!C31 -> Aluguel | E31: ='Orçamento Familiar'!E31 -> 0 | F31: =P31 -> 0 | G31: =E31-F31 -> 0 | P31: =SUM(I31:O31) -> 0
C32: ='Orçamento Familiar'!C32 -> Energia Elétrica | E32: ='Orçamento Familiar'!E32 -> 0 | F32: =P32 -> 0 | G32: =E32-F32 -> 0 | P32: =SUM(I32:O32) -> 0
C33: ='Orçamento Familiar'!C33 -> Água e Esgoto | E33: ='Orçamento Familiar'!E33 -> 0 | F33: =P33 -> 0 | G33: =E33-F33 -> 0 | P33: =SUM(I33:O33) -> 0
C34: ='Orçamento Familiar'!C34 -> Gás | E34: ='Orçamento Familiar'!E34 -> 0 | F34: =P34 -> 0 | G34: =E34-F34 -> 0 | P34: =SUM(I34:O34) -> 0
C35: ='Orçamento Familiar'!C35 -> Internet e Celular | E35: ='Orçamento Familiar'!E35 -> 125 | F35: =P35 -> 0 | G35: =E35-F35 -> 125 | P35: =SUM(I35:O35) -> 0
C36: ='Orçamento Familiar'!C36 -> Manutenção | E36: ='Orçamento Familiar'!E36 -> 0 | F36: =P36 -> 0 | G36: =E36-F36 -> 0 | P36: =SUM(I36:O36) -> 0
C37: ='Orçamento Familiar'!C37 -> 0 | E37: ='Orçamento Familiar'!E37 -> 0 | F37: =P37 -> 0 | G37: =E37-F37 -> 0 | P37: =SUM(I37:O37) -> 0
C38: ='Orçamento Familiar'!C38 -> 0 | E38: ='Orçamento Familiar'!E38 -> 0 | F38: =P38 -> 0 | G38: =E38-F38 -> 0 | P38: =SUM(I38:O38) -> 0
C39: ='Orçamento Familiar'!C39 -> 0 | E39: ='Orçamento Familiar'!E39 -> 0 | F39: =P39 -> 0 | G39: =E39-F39 -> 0 | P39: =SUM(I39:O39) -> 0
B40: Alimentação | C40: ='Orçamento Familiar'!C40 -> Supermercado | E40: ='Orçamento Familiar'!E40 -> 3100 | F40: =P40 -> 1942.99 | G40: =E40-F40 -> 1157.01 | I40: 313 | J40: 329.03 | K40: =339.97+129 -> 468.97 | L40: 467.43 | M40: 364.56 | P40: =SUM(I40:O40) -> 1942.99
C41: ='Orçamento Familiar'!C41 -> 0 | E41: ='Orçamento Familiar'!E41 -> 0 | F41: =P41 -> 0 | G41: =E41-F41 -> 0 | P41: =SUM(I41:O41) -> 0
C42: ='Orçamento Familiar'!C42 -> 0 | E42: ='Orçamento Familiar'!E42 -> 0 | F42: =P42 -> 0 | G42: =E42-F42 -> 0 | P42: =SUM(I42:O42) -> 0
C43: ='Orçamento Familiar'!C43 -> 0 | E43: ='Orçamento Familiar'!E43 -> 0 | F43: =P43 -> 0 | G43: =E43-F43 -> 0 | P43: =SUM(I43:O43) -> 0
C44: ='Orçamento Familiar'!C44 -> 0 | E44: ='Orçamento Familiar'!E44 -> 0 | F44: =P44 -> 0 | G44: =E44-F44 -> 0 | P44: =SUM(I44:O44) -> 0
C45: ='Orçamento Familiar'!C45 -> 0 | E45: ='Orçamento Familiar'!E45 -> 0 | F45: =P45 -> 0 | G45: =E45-F45 -> 0 | P45: =SUM(I45:O45) -> 0
...

Sheet Fev
A2: Fluxo de Caixa Familiar
A5: Categoria | C5: Descrição | D5: Percentual | E5: =I5 -> Fevereiro | I5: Fevereiro
E6: Orçado | F6: Realizado | G6: Variação | I6: Semana 1 | J6: Semana 2 | K6: Semana 3 | L6: Semana 4 | M6: Semana 5 | N6: =Jan!N6 -> Cartão Nubank | O6: =Jan!O6 -> Cartão C & A | P6: Total
A7: Receitas | C7: ='Orçamento Familiar'!C7 -> Prebenda | E7: ='Orçamento Familiar'!F7 -> 7216 | F7: =P7 -> 5716 | G7: =F7-E7 -> -1500 | I7: 5716 | P7: =SUM(I7:O7) -> 5716
C8: ='Orçamento Familiar'!C8 -> Inglês | E8: ='Orçamento Familiar'!F8 -> 340 | F8: =P8 -> 335 | G8: =F8-E8 -> -5 | I8: 200 | L8: 135 | P8: =SUM(I8:O8) -> 335
C9: ='Orçamento Familiar'!C9 -> 13º Salário | E9: ='Orçamento Familiar'!F9 -> 0 | F9: =P9 -> 0 | G9: =F9-E9 -> 0 | P9: =SUM(I9:O9) -> 0
C10: ='Orçamento Familiar'!C10 -> Renda Extra | E10: ='Orçamento Familiar'!F10 -> 0 | F10: =P10 -> 1248 | G10: =F10-E10 -> 1248 | J10: 300 | K10: 460 | L10: 160 | M10: 328 | P10: =SUM(I10:O10) -> 1248 | Q10: Faxina japonês=300,00/ renda Eric 660,00 / 160,00=OFERTA / Eric=328,00
C11: ='Orçamento Familiar'!C11 -> 0 | E11: ='Orçamento Familiar'!F11 -> 0 | F11: =P11 -> 0 | G11: =F11-E11 -> 0 | P11: =SUM(I11:O11) -> 0
C12: ='Orçamento Familiar'!C12 -> 0 | E12: ='Orçamento Familiar'!F12 -> 0 | F12: =P12 -> 0 | G12: =F12-E12 -> 0 | P12: =SUM(I12:O12) -> 0
C13: ='Orçamento Familiar'!C13 -> 0 | E13: ='Orçamento Familiar'!F13 -> 0 | F13: =P13 -> 1500 | G13: =F13-E13 -> 1500 | J13: 1500 | P13: =SUM(I13:O13) -> 1500
C14: ='Orçamento Familiar'!C14 -> 0 | E14: ='Orçamento Familiar'!F14 -> 0 | F14: =P14 -> 0 | G14: =F14-E14 -> 0 | P14: =SUM(I14:O14) -> 0
C15: ='Orçamento Familiar'!C15 -> 0 | E15: ='Orçamento Familiar'!F15 -> 0 | F15: =P15 -> 0 | G15: =F15-E15 -> 0 | P15: =SUM(I15:O15) -> 0
C16: Total | E16: =SUM(E7:E15) -> 7556 | F16: =SUM(F7:F15) -> 8799 | G16: =SUM(G7:G15) -> 1243 | I16: =SUM(I7:I15) -> 5916 | J16: =SUM(J7:J15) -> 1800 | K16: =SUM(K7:K15) -> 460 | L16: =SUM(L7:L15) -> 295 | M16: =SUM(M7:M15) -> 328 | N16: =SUM(N7:N15) -> 0 | O16: =SUM(O7:O15) -> 0 | P16: =SUM(P7:P15) -> 8799
A18: Investimentos Insira aqui o montante mensal que você destinará aos seus investimentos | C18: Descrição | D18: Percentual | E18: Orçado | F18: Realizado | G18: Variação | I18: =I6 -> Semana 1 | J18: =J6 -> Semana 2 | K18: =K6 -> Semana 3 | L18: =L6 -> Semana 4 | M18: =M6 -> Semana 5 | P18: =P6 -> Total
C19: ='Orçamento Familiar'!C19 -> Reserva de Emergência (CP) R$ 9.151 | E19: ='Orçamento Familiar'!F19 -> 0 | F19: =P19 -> 0 | G19: =F19-E19 -> 0 | P19: =SUM(I19:O19) -> 0
C20: ='Orçamento Familiar'!C20 -> Projeto 1 | E20: ='Orçamento Familiar'!F20 -> 0 | F20: =P20 -> 0 | G20: =F20-E20 -> 0 | P20: =SUM(I20:O20) -> 0
C21: ='Orçamento Familiar'!C21 -> Projeto 2 | E21: ='Orçamento Familiar'!F21 -> 0 | F21: =P21 -> 0 | G21: =F21-E21 -> 0 | P21: =SUM(I21:O21) -> 0
C22: ='Orçamento Familiar'!C22 -> Projeto 3 | E22: ='Orçamento Familiar'!F22 -> 0 | F22: =P22 -> 0 | G22: =F22-E22 -> 0 | P22: =SUM(I22:O22) -> 0
C23: ='Orçamento Familiar'!C23 -> Projeto 4 | E23: ='Orçamento Familiar'!F23 -> 0 | F23: =P23 -> 0 | G23: =F23-E23 -> 0 | P23: =SUM(I23:O23) -> 0
C24: ='Orçamento Familiar'!C24 -> Projeto 5 | E24: ='Orçamento Familiar'!F24 -> 0 | F24: =P24 -> 0 | G24: =F24-E24 -> 0 | P24: =SUM(I24:O24) -> 0
C25: ='Orçamento Familiar'!C25 -> Projeto 6 | E25: ='Orçamento Familiar'!F25 -> 0 | F25: =P25 -> 0 | G25: =F25-E25 -> 0 | P25: =SUM(I25:O25) -> 0
C26: ='Orçamento Familiar'!C26 -> Independência Financeira | E26: ='Orçamento Familiar'!F26 -> 0 | F26: =P26 -> 0 | G26: =F26-E26 -> 0 | P26: =SUM(I26:O26) -> 0
C27: Total Investimentos | D27: =SUM(D19:D26) -> 0 | E27: =SUM(E19:E26) -> 0 | F27: =SUM(F19:F26) -> 0 | G27: =SUM(G19:G26) -> 0 | I27: =SUM(I19:I26) -> 0 | J27: =SUM(J19:J26) -> 0 | K27: =SUM(K19:K26) -> 0 | L27: =SUM(L19:L26) -> 0 | M27: =SUM(M19:M26) -> 0 | N27: =SUM(N19:N26) -> 0 | O27: =SUM(O19:O26) -> 0 | P27: =SUM(P19:P26) -> 0
C28: % sobre Receita | E28: =E27/E16 -> 0 | F28: =F27/F16 -> 0 | I28: =I27/I16 -> 0 | J28: =J27/J16 -> 0 | K28: =K27/K16 -> 0 | L28: =L27/L16 -> 0 | M28: =M27/M16 -> 0 | N28: =N27/N16 -> #DIV/0! | O28: =O27/O16 -> #DIV/0! | P28: =P27/P16 -> 0
A30: Categoria | C30: Descrição | D30: Percentual | E30: Orçado | F30: Realizado | G30: Variação | I30: =I18 -> Semana 1 | J30: =J18 -> Semana 2 | K30: =K18 -> Semana 3 | L30: =L18 -> Semana 4 | M30: =M18 -> Semana 5 | N30: =N6 -> Cartão Nubank | O30: =O6 -> Cartão C & A | P30: =P18 -> Total
A31: Despesas Essenciais | B31: Moradia | C31: ='Orçamento Familiar'!C31 -> Aluguel | E31: ='Orçamento Familiar'!F31 -> 0 | F31: =P31 -> 0 | G31: =E31-F31 -> 0 | P31: =SUM(I31:O31) -> 0
C32: ='Orçamento Familiar'!C32 -> Energia Elétrica | E32: ='Orçamento Familiar'!F32 -> 0 | F32: =P32 -> 0 | G32: =E32-F32 -> 0 | P32: =SUM(I32:O32) -> 0
C33: ='Orçamento Familiar'!C33 -> Água e Esgoto | E33: ='Orçamento Familiar'!F33 -> 0 | F33: =P33 -> 0 | G33: =E33-F33 -> 0 | P33: =SUM(I33:O33) -> 0
C34: ='Orçamento Familiar'!C34 -> Gás | E34: ='Orçamento Familiar'!F34 -> 0 | F34: =P34 -> 0 | G34: =E34-F34 -> 0 | P34: =SUM(I34:O34) -> 0
C35: ='Orçamento Familiar'!C35 -> Internet e Celular | E35: ='Orçamento Familiar'!F35 -> 125 | F35: =P35 -> 185.7 | G35: =E35-F35 -> -60.7 | N35: 185.7 | P35: =SUM(I35:O35) -> 185.7
C36: ='Orçamento Familiar'!C36 -> Manutenção | E36: ='Orçamento Familiar'!F36 -> 0 | F36: =P36 -> 60 | G36: =E36-F36 -> -60 | I36: 60 | P36: =SUM(I36:O36) -> 60
C37: ='Orçamento Familiar'!C37 -> 0 | E37: ='Orçamento Familiar'!F37 -> 0 | F37: =P37 -> 69 | G37: =E37-F37 -> -69 | I37: 69 | P37: =SUM(I37:O37) -> 69
C38: ='Orçamento Familiar'!C38 -> 0 | E38: ='Orçamento Familiar'!F38 -> 0 | F38: =P38 -> 0 | G38: =E38-F38 -> 0 | P38: =SUM(I38:O38) -> 0
C39: ='Orçamento Familiar'!C39 -> 0 | E39: ='Orçamento Familiar'!F39 -> 0 | F39: =P39 -> 0 | G39: =E39-F39 -> 0 | P39: =SUM(I39:O39) -> 0
B40: Alimentação | C40: ='Orçamento Familiar'!C40 -> Supermercado | E40: ='Orçamento Familiar'!F40 -> 3100 | F40: =P40 -> 3370.53 | G40: =E40-F40 -> -270.53 | I40: =644.79+42 -> 686.79 | J40: =1100+30.85 -> 1130.85 | K40: =615.88+103.98 -> 719.86 | L40: =287.35+80 -> 367.35 | M40: 379.21 | N40: 86.47 | P40: =SUM(I40:O40) -> 3370.53
C41: ='Orçamento Familiar'!C41 -> 0 | E41: ='Orçamento Familiar'!F41 -> 0 | F41: =P41 -> 0 | G41: =E41-F41 -> 0 | P41: =SUM(I41:O41) -> 0
C42: ='Orçamento Familiar'!C42 -> 0 | E42: ='Orçamento Familiar'!F42 -> 0 | F42: =P42 -> 0 | G42: =E42-F42 -> 0 | P42: =SUM(I42:O42) -> 0
C43: ='Orçamento Familiar'!C43 -> 0 | E43: ='Orçamento Familiar'!F43 -> 0 | F43: =P43 -> 0 | G43: =E43-F43 -> 0 | P43: =SUM(I43:O43) -> 0
C44: ='Orçamento Familiar'!C44 -> 0 | E44: ='Orçamento Familiar'!F44 -> 0 | F44: =P44 -> 0 | G44: =E44-F44 -> 0 | P44: =SUM(I44:O44) -> 0
C45: ='Orçamento Familiar'!C45 -> 0 | E45: ='Orçamento Familiar'!F45 -> 0 | F45: =P45 -> 0 | G45: =E45-F45 -> 0 | P45: =SUM(I45:O45) -> 0
...

Sheet Mar
A2: Fluxo de Caixa Familiar
A5: Categoria | C5: Descrição | D5: Percentual | E5: =I5 -> Março | I5: Março
E6: Orçado | F6: Realizado | G6: Variação | I6: Semana 1 | J6: Semana 2 | K6: Semana 3 | L6: Semana 4 | M6: Semana 5 | N6: =Jan!N6 -> Cartão Nubank | O6: =Jan!O6 -> Cartão C & A | P6: Total
A7: Receitas | C7: ='Orçamento Familiar'!C7 -> Prebenda | E7: ='Orçamento Familiar'!G7 -> 7216 | F7: =P7 -> 5716 | G7: =F7-E7 -> -1500 | I7: 5716 | P7: =SUM(I7:O7) -> 5716
C8: ='Orçamento Familiar'!C8 -> Inglês | E8: ='Orçamento Familiar'!G8 -> 335 | F8: =P8 -> 200 | G8: =F8-E8 -> -135 | I8: 200 | P8: =SUM(I8:O8) -> 200
C9: ='Orçamento Familiar'!C9 -> 13º Salário | E9: ='Orçamento Familiar'!G9 -> 0 | F9: =P9 -> 0 | G9: =F9-E9 -> 0 | P9: =SUM(I9:O9) -> 0
C10: ='Orçamento Familiar'!C10 -> Renda Extra | E10: ='Orçamento Familiar'!G10 -> 0 | F10: =P10 -> 0 | G10: =F10-E10 -> 0 | P10: =SUM(I10:O10) -> 0
C11: ='Orçamento Familiar'!C11 -> 0 | E11: ='Orçamento Familiar'!G11 -> 0 | F11: =P11 -> 0 | G11: =F11-E11 -> 0 | P11: =SUM(I11:O11) -> 0
C12: ='Orçamento Familiar'!C12 -> 0 | E12: ='Orçamento Familiar'!G12 -> 0 | F12: =P12 -> 0 | G12: =F12-E12 -> 0 | P12: =SUM(I12:O12) -> 0
C13: ='Orçamento Familiar'!C13 -> 0 | E13: ='Orçamento Familiar'!G13 -> 0 | F13: =P13 -> 128 | G13: =F13-E13 -> 128 | I13: 128 | P13: =SUM(I13:O13) -> 128 | Q13: 128,00 Eric
C14: ='Orçamento Familiar'!C14 -> 0 | E14: ='Orçamento Familiar'!G14 -> 0 | F14: =P14 -> 0 | G14: =F14-E14 -> 0 | P14: =SUM(I14:O14) -> 0
C15: ='Orçamento Familiar'!C15 -> 0 | E15: ='Orçamento Familiar'!G15 -> 0 | F15: =P15 -> 0 | G15: =F15-E15 -> 0 | P15: =SUM(I15:O15) -> 0
C16: Total | E16: =SUM(E7:E15) -> 7551 | F16: =SUM(F7:F15) -> 6044 | G16: =SUM(G7:G15) -> -1507 | I16: =SUM(I7:I15) -> 6044 | J16: =SUM(J7:J15) -> 0 | K16: =SUM(K7:K15) -> 0 | L16: =SUM(L7:L15) -> 0 | M16: =SUM(M7:M15) -> 0 | N16: =SUM(N7:N15) -> 0 | O16: =SUM(O7:O15) -> 0 | P16: =SUM(P7:P15) -> 6044
A18: Investimentos Insira aqui o montante mensal que você destinará aos seus investimentos | C18: Descrição | D18: Percentual | E18: Orçado | F18: Realizado | G18: Variação | I18: =I6 -> Semana 1 | J18: =J6 -> Semana 2 | K18: =K6 -> Semana 3 | L18: =L6 -> Semana 4 | M18: =M6 -> Semana 5 | P18: =P6 -> Total
C19: ='Orçamento Familiar'!C19 -> Reserva de Emergência (CP) R$ 9.151 | E19: ='Orçamento Familiar'!G19 -> 0 | F19: =P19 -> 0 | G19: =F19-E19 -> 0 | P19: =SUM(I19:O19) -> 0
C20: ='Orçamento Familiar'!C20 -> Projeto 1 | E20: ='Orçamento Familiar'!G20 -> 0 | F20: =P20 -> 0 | G20: =F20-E20 -> 0 | P20: =SUM(I20:O20) -> 0
C21: ='Orçamento Familiar'!C21 -> Projeto 2 | E21: ='Orçamento Familiar'!G21 -> 0 | F21: =P21 -> 0 | G21: =F21-E21 -> 0 | P21: =SUM(I21:O21) -> 0
C22: ='Orçamento Familiar'!C22 -> Projeto 3 | E22: ='Orçamento Familiar'!G22 -> 0 | F22: =P22 -> 0 | G22: =F22-E22 -> 0 | P22: =SUM(I22:O22) -> 0
C23: ='Orçamento Familiar'!C23 -> Projeto 4 | E23: ='Orçamento Familiar'!G23 -> 0 | F23: =P23 -> 0 | G23: =F23-E23 -> 0 | P23: =SUM(I23:O23) -> 0
C24: ='Orçamento Familiar'!C24 -> Projeto 5 | E24: ='Orçamento Familiar'!G24 -> 0 | F24: =P24 -> 0 | G24: =F24-E24 -> 0 | P24: =SUM(I24:O24) -> 0
C25: ='Orçamento Familiar'!C25 -> Projeto 6 | E25: ='Orçamento Familiar'!G25 -> 0 | F25: =P25 -> 0 | G25: =F25-E25 -> 0 | P25: =SUM(I25:O25) -> 0
C26: ='Orçamento Familiar'!C26 -> Independência Financeira | E26: ='Orçamento Familiar'!G26 -> 0 | F26: =P26 -> 0 | G26: =F26-E26 -> 0 | P26: =SUM(I26:O26) -> 0
C27: Total Investimentos | D27: =SUM(D19:D26) -> 0 | E27: =SUM(E19:E26) -> 0 | F27: =SUM(F19:F26) -> 0 | G27: =SUM(G19:G26) -> 0 | I27: =SUM(I19:I26) -> 0 | J27: =SUM(J19:J26) -> 0 | K27: =SUM(K19:K26) -> 0 | L27: =SUM(L19:L26) -> 0 | M27: =SUM(M19:M26) -> 0 | N27: =SUM(N19:N26) -> 0 | O27: =SUM(O19:O26) -> 0 | P27: =SUM(P19:P26) -> 0
C28: % sobre Receita | E28: =E27/E16 -> 0 | F28: =F27/F16 -> 0 | I28: =I27/I16 -> 0 | J28: =J27/J16 -> #DIV/0! | K28: =K27/K16 -> #DIV/0! | L28: =L27/L16 -> #DIV/0! | M28: =M27/M16 -> #DIV/0! | N28: =N27/N16 -> #DIV/0! | O28: =O27/O16 -> #DIV/0! | P28: =P27/P16 -> 0
A30: Categoria | C30: Descrição | D30: Percentual | E30: Orçado | F30: Realizado | G30: Variação | I30: =I18 -> Semana 1 | J30: =J18 -> Semana 2 | K30: =K18 -> Semana 3 | L30: =L18 -> Semana 4 | M30: =M18 -> Semana 5 | N30: =N6 -> Cartão Nubank | O30: =O6 -> Cartão C & A | P30: =P18 -> Total
A31: Despesas Essenciais | B31: Moradia | C31: ='Orçamento Familiar'!C31 -> Aluguel | E31: ='Orçamento Familiar'!G31 -> 0 | F31: =P31 -> 0 | G31: =E31-F31 -> 0 | P31: =SUM(I31:O31) -> 0
C32: ='Orçamento Familiar'!C32 -> Energia Elétrica | E32: ='Orçamento Familiar'!G32 -> 0 | F32: =P32 -> 0 | G32: =E32-F32 -> 0 | P32: =SUM(I32:O32) -> 0
C33: ='Orçamento Familiar'!C33 -> Água e Esgoto | E33: ='Orçamento Familiar'!G33 -> 0 | F33: =P33 -> 0 | G33: =E33-F33 -> 0 | P33: =SUM(I33:O33) -> 0
C34: ='Orçamento Familiar'!C34 -> Gás | E34: ='Orçamento Familiar'!G34 -> 0 | F34: =P34 -> 0 | G34: =E34-F34 -> 0 | P34: =SUM(I34:O34) -> 0
C35: ='Orçamento Familiar'!C35 -> Internet e Celular | E35: ='Orçamento Familiar'!G35 -> 184.7 | F35: =P35 -> 184.7 | G35: =E35-F35 -> 0 | N35: 184.7 | P35: =SUM(I35:O35) -> 184.7
C36: ='Orçamento Familiar'!C36 -> Manutenção | E36: ='Orçamento Familiar'!G36 -> 50 | F36: =P36 -> 0 | G36: =E36-F36 -> 50 | P36: =SUM(I36:O36) -> 0
C37: ='Orçamento Familiar'!C37 -> 0 | E37: ='Orçamento Familiar'!G37 -> 0 | F37: =P37 -> 0 | G37: =E37-F37 -> 0 | P37: =SUM(I37:O37) -> 0
C38: ='Orçamento Familiar'!C38 -> 0 | E38: ='Orçamento Familiar'!G38 -> 0 | F38: =P38 -> 0 | G38: =E38-F38 -> 0 | P38: =SUM(I38:O38) -> 0
C39: ='Orçamento Familiar'!C39 -> 0 | E39: ='Orçamento Familiar'!G39 -> 0 | F39: =P39 -> 0 | G39: =E39-F39 -> 0 | P39: =SUM(I39:O39) -> 0
B40: Alimentação | C40: ='Orçamento Familiar'!C40 -> Supermercado | E40: ='Orçamento Familiar'!G40 -> 3100 | F40: =P40 -> 2410.57 | G40: =E40-F40 -> 689.43 | I40: 317.1 | J40: =740+133.5 -> 873.5 | K40: 450.3 | N40: 769.67 | P40: =SUM(I40:O40) -> 2410.57
C41: ='Orçamento Familiar'!C41 -> 0 | E41: ='Orçamento Familiar'!G41 -> 0 | F41: =P41 -> 0 | G41: =E41-F41 -> 0 | P41: =SUM(I41:O41) -> 0
C42: ='Orçamento Familiar'!C42 -> 0 | E42: ='Orçamento Familiar'!G42 -> 0 | F42: =P42 -> 0 | G42: =E42-F42 -> 0 | P42: =SUM(I42:O42) -> 0
C43: ='Orçamento Familiar'!C43 -> 0 | E43: ='Orçamento Familiar'!G43 -> 0 | F43: =P43 -> 0 | G43: =E43-F43 -> 0 | P43: =SUM(I43:O43) -> 0
C44: ='Orçamento Familiar'!C44 -> 0 | E44: ='Orçamento Familiar'!G44 -> 0 | F44: =P44 -> 0 | G44: =E44-F44 -> 0 | P44: =SUM(I44:O44) -> 0
C45: ='Orçamento Familiar'!C45 -> 0 | E45: ='Orçamento Familiar'!G45 -> 0 | F45: =P45 -> 0 | G45: =E45-F45 -> 0 | P45: =SUM(I45:O45) -> 0
...

Sheet Abr
A2: Fluxo de Caixa Familiar
A5: Categoria | C5: Descrição | D5: Percentual | E5: =I5 -> Abril | I5: Abril
E6: Orçado | F6: Realizado | G6: Variação | I6: Semana 1 | J6: Semana 2 | K6: Semana 3 | L6: Semana 4 | M6: Semana 5 | N6: =Jan!N6 -> Cartão Nubank | O6: =Jan!O6 -> Cartão C & A | P6: Total
A7: Receitas | C7: ='Orçamento Familiar'!C7 -> Prebenda | E7: ='Orçamento Familiar'!H7 -> 7216 | F7: =P7 -> 0 | G7: =F7-E7 -> -7216 | P7: =SUM(I7:O7) -> 0
C8: ='Orçamento Familiar'!C8 -> Inglês | E8: ='Orçamento Familiar'!H8 -> 335 | F8: =P8 -> 0 | G8: =F8-E8 -> -335 | P8: =SUM(I8:O8) -> 0
C9: ='Orçamento Familiar'!C9 -> 13º Salário | E9: ='Orçamento Familiar'!H9 -> 0 | F9: =P9 -> 0 | G9: =F9-E9 -> 0 | P9: =SUM(I9:O9) -> 0
C10: ='Orçamento Familiar'!C10 -> Renda Extra | E10: ='Orçamento Familiar'!H10 -> 0 | F10: =P10 -> 0 | G10: =F10-E10 -> 0 | P10: =SUM(I10:O10) -> 0
C11: ='Orçamento Familiar'!C11 -> 0 | E11: ='Orçamento Familiar'!H11 -> 0 | F11: =P11 -> 0 | G11: =F11-E11 -> 0 | P11: =SUM(I11:O11) -> 0
C12: ='Orçamento Familiar'!C12 -> 0 | E12: ='Orçamento Familiar'!H12 -> 0 | F12: =P12 -> 0 | G12: =F12-E12 -> 0 | P12: =SUM(I12:O12) -> 0
C13: ='Orçamento Familiar'!C13 -> 0 | E13: ='Orçamento Familiar'!H13 -> 0 | F13: =P13 -> 0 | G13: =F13-E13 -> 0 | P13: =SUM(I13:O13) -> 0
C14: ='Orçamento Familiar'!C14 -> 0 | E14: ='Orçamento Familiar'!H14 -> 0 | F14: =P14 -> 0 | G14: =F14-E14 -> 0 | P14: =SUM(I14:O14) -> 0
C15: ='Orçamento Familiar'!C15 -> 0 | E15: ='Orçamento Familiar'!H15 -> 0 | F15: =P15 -> 0 | G15: =F15-E15 -> 0 | P15: =SUM(I15:O15) -> 0
C16: Total | E16: =SUM(E7:E15) -> 7551 | F16: =SUM(F7:F15) -> 0 | G16: =SUM(G7:G15) -> -7551 | I16: =SUM(I7:I15) -> 0 | J16: =SUM(J7:J15) -> 0 | K16: =SUM(K7:K15) -> 0 | L16: =SUM(L7:L15) -> 0 | M16: =SUM(M7:M15) -> 0 | N16: =SUM(N7:N15) -> 0 | O16: =SUM(O7:O15) -> 0 | P16: =SUM(P7:P15) -> 0
A18: Investimentos Insira aqui o montante mensal que você destinará aos seus investimentos | C18: Descrição | D18: Percentual | E18: Orçado | F18: Realizado | G18: Variação | I18: =I6 -> Semana 1 | J18: =J6 -> Semana 2 | K18: =K6 -> Semana 3 | L18: =L6 -> Semana 4 | M18: =M6 -> Semana 5 | P18: =P6 -> Total
C19: ='Orçamento Familiar'!C19 -> Reserva de Emergência (CP) R$ 9.151 | E19: ='Orçamento Familiar'!H19 -> 0 | F19: =P19 -> 0 | G19: =F19-E19 -> 0 | P19: =SUM(I19:O19) -> 0
C20: ='Orçamento Familiar'!C20 -> Projeto 1 | E20: ='Orçamento Familiar'!H20 -> 0 | F20: =P20 -> 0 | G20: =F20-E20 -> 0 | P20: =SUM(I20:O20) -> 0
C21: ='Orçamento Familiar'!C21 -> Projeto 2 | E21: ='Orçamento Familiar'!H21 -> 0 | F21: =P21 -> 0 | G21: =F21-E21 -> 0 | P21: =SUM(I21:O21) -> 0
C22: ='Orçamento Familiar'!C22 -> Projeto 3 | E22: ='Orçamento Familiar'!H22 -> 0 | F22: =P22 -> 0 | G22: =F22-E22 -> 0 | P22: =SUM(I22:O22) -> 0
C23: ='Orçamento Familiar'!C23 -> Projeto 4 | E23: ='Orçamento Familiar'!H23 -> 0 | F23: =P23 -> 0 | G23: =F23-E23 -> 0 | P23: =SUM(I23:O23) -> 0
C24: ='Orçamento Familiar'!C24 -> Projeto 5 | E24: ='Orçamento Familiar'!H24 -> 0 | F24: =P24 -> 0 | G24: =F24-E24 -> 0 | P24: =SUM(I24:O24) -> 0
C25: ='Orçamento Familiar'!C25 -> Projeto 6 | E25: ='Orçamento Familiar'!H25 -> 0 | F25: =P25 -> 0 | G25: =F25-E25 -> 0 | P25: =SUM(I25:O25) -> 0
C26: ='Orçamento Familiar'!C26 -> Independência Financeira | E26: ='Orçamento Familiar'!H26 -> 0 | F26: =P26 -> 0 | G26: =F26-E26 -> 0 | P26: =SUM(I26:O26) -> 0
C27: Total Investimentos | D27: =SUM(D19:D26) -> 0 | E27: =SUM(E19:E26) -> 0 | F27: =SUM(F19:F26) -> 0 | G27: =SUM(G19:G26) -> 0 | I27: =SUM(I19:I26) -> 0 | J27: =SUM(J19:J26) -> 0 | K27: =SUM(K19:K26) -> 0 | L27: =SUM(L19:L26) -> 0 | M27: =SUM(M19:M26) -> 0 | N27: =SUM(N19:N26) -> 0 | O27: =SUM(O19:O26) -> 0 | P27: =SUM(P19:P26) -> 0
C28: % sobre Receita | E28: =E27/E16 -> 0 | F28: =F27/F16 -> #DIV/0! | I28: =I27/I16 -> #DIV/0! | J28: =J27/J16 -> #DIV/0! | K28: =K27/K16 -> #DIV/0! | L28: =L27/L16 -> #DIV/0! | M28: =M27/M16 -> #DIV/0! | N28: =N27/N16 -> #DIV/0! | O28: =O27/O16 -> #DIV/0! | P28: =P27/P16 -> #DIV/0!
A30: Categoria | C30: Descrição | D30: Percentual | E30: Orçado | F30: Realizado | G30: Variação | I30: =I18 -> Semana 1 | J30: =J18 -> Semana 2 | K30: =K18 -> Semana 3 | L30: =L18 -> Semana 4 | M30: =M18 -> Semana 5 | N30: =N6 -> Cartão Nubank | O30: =O6 -> Cartão C & A | P30: =P18 -> Total
A31: Despesas Essenciais | B31: Moradia | C31: ='Orçamento Familiar'!C31 -> Aluguel | E31: ='Orçamento Familiar'!H31 -> 0 | F31: =P31 -> 0 | G31: =E31-F31 -> 0 | P31: =SUM(I31:O31) -> 0
C32: ='Orçamento Familiar'!C32 -> Energia Elétrica | E32: ='Orçamento Familiar'!H32 -> 0 | F32: =P32 -> 0 | G32: =E32-F32 -> 0 | P32: =SUM(I32:O32) -> 0
C33: ='Orçamento Familiar'!C33 -> Água e Esgoto | E33: ='Orçamento Familiar'!H33 -> 0 | F33: =P33 -> 0 | G33: =E33-F33 -> 0 | P33: =SUM(I33:O33) -> 0
C34: ='Orçamento Familiar'!C34 -> Gás | E34: ='Orçamento Familiar'!H34 -> 0 | F34: =P34 -> 0 | G34: =E34-F34 -> 0 | P34: =SUM(I34:O34) -> 0
C35: ='Orçamento Familiar'!C35 -> Internet e Celular | E35: ='Orçamento Familiar'!H35 -> 184.7 | F35: =P35 -> 0 | G35: =E35-F35 -> 184.7 | P35: =SUM(I35:O35) -> 0
C36: ='Orçamento Familiar'!C36 -> Manutenção | E36: ='Orçamento Familiar'!H36 -> 50 | F36: =P36 -> 0 | G36: =E36-F36 -> 50 | P36: =SUM(I36:O36) -> 0
C37: ='Orçamento Familiar'!C37 -> 0 | E37: ='Orçamento Familiar'!H37 -> 0 | F37: =P37 -> 0 | G37: =E37-F37 -> 0 | P37: =SUM(I37:O37) -> 0
C38: ='Orçamento Familiar'!C38 -> 0 | E38: ='Orçamento Familiar'!H38 -> 0 | F38: =P38 -> 0 | G38: =E38-F38 -> 0 | P38: =SUM(I38:O38) -> 0
C39: ='Orçamento Familiar'!C39 -> 0 | E39: ='Orçamento Familiar'!H39 -> 0 | F39: =P39 -> 0 | G39: =E39-F39 -> 0 | P39: =SUM(I39:O39) -> 0
B40: Alimentação | C40: ='Orçamento Familiar'!C40 -> Supermercado | E40: ='Orçamento Familiar'!H40 -> 3100 | F40: =P40 -> 366.88 | G40: =E40-F40 -> 2733.12 | N40: 366.88 | P40: =SUM(I40:O40) -> 366.88
C41: ='Orçamento Familiar'!C41 -> 0 | E41: ='Orçamento Familiar'!H41 -> 0 | F41: =P41 -> 0 | G41: =E41-F41 -> 0 | P41: =SUM(I41:O41) -> 0
C42: ='Orçamento Familiar'!C42 -> 0 | E42: ='Orçamento Familiar'!H42 -> 0 | F42: =P42 -> 0 | G42: =E42-F42 -> 0 | P42: =SUM(I42:O42) -> 0
C43: ='Orçamento Familiar'!C43 -> 0 | E43: ='Orçamento Familiar'!H43 -> 0 | F43: =P43 -> 0 | G43: =E43-F43 -> 0 | P43: =SUM(I43:O43) -> 0
C44: ='Orçamento Familiar'!C44 -> 0 | E44: ='Orçamento Familiar'!H44 -> 0 | F44: =P44 -> 0 | G44: =E44-F44 -> 0 | P44: =SUM(I44:O44) -> 0
C45: ='Orçamento Familiar'!C45 -> 0 | E45: ='Orçamento Familiar'!H45 -> 0 | F45: =P45 -> 0 | G45: =E45-F45 -> 0 | P45: =SUM(I45:O45) -> 0
...

Sheet Mai
A2: Fluxo de Caixa Familiar
A5: Categoria | C5: Descrição | D5: Percentual | E5: =I5 -> Maio | I5: Maio
E6: Orçado | F6: Realizado | G6: Variação | I6: Semana 1 | J6: Semana 2 | K6: Semana 3 | L6: Semana 4 | M6: Semana 5 | N6: =Jan!N6 -> Cartão Nubank | O6: =Jan!O6 -> Cartão C & A | P6: Total
A7: Receitas | C7: ='Orçamento Familiar'!C7 -> Prebenda | E7: ='Orçamento Familiar'!I7 -> 7216 | F7: =P7 -> 0 | G7: =F7-E7 -> -7216 | P7: =SUM(I7:O7) -> 0
C8: ='Orçamento Familiar'!C8 -> Inglês | E8: ='Orçamento Familiar'!I8 -> 335 | F8: =P8 -> 0 | G8: =F8-E8 -> -335 | P8: =SUM(I8:O8) -> 0
C9: ='Orçamento Familiar'!C9 -> 13º Salário | E9: ='Orçamento Familiar'!I9 -> 0 | F9: =P9 -> 0 | G9: =F9-E9 -> 0 | P9: =SUM(I9:O9) -> 0
C10: ='Orçamento Familiar'!C10 -> Renda Extra | E10: ='Orçamento Familiar'!I10 -> 0 | F10: =P10 -> 0 | G10: =F10-E10 -> 0 | P10: =SUM(I10:O10) -> 0
C11: ='Orçamento Familiar'!C11 -> 0 | E11: ='Orçamento Familiar'!I11 -> 0 | F11: =P11 -> 0 | G11: =F11-E11 -> 0 | P11: =SUM(I11:O11) -> 0
C12: ='Orçamento Familiar'!C12 -> 0 | E12: ='Orçamento Familiar'!I12 -> 0 | F12: =P12 -> 0 | G12: =F12-E12 -> 0 | P12: =SUM(I12:O12) -> 0
C13: ='Orçamento Familiar'!C13 -> 0 | E13: ='Orçamento Familiar'!I13 -> 0 | F13: =P13 -> 0 | G13: =F13-E13 -> 0 | P13: =SUM(I13:O13) -> 0
C14: ='Orçamento Familiar'!C14 -> 0 | E14: ='Orçamento Familiar'!I14 -> 0 | F14: =P14 -> 0 | G14: =F14-E14 -> 0 | P14: =SUM(I14:O14) -> 0
C15: ='Orçamento Familiar'!C15 -> 0 | E15: ='Orçamento Familiar'!I15 -> 0 | F15: =P15 -> 0 | G15: =F15-E15 -> 0 | P15: =SUM(I15:O15) -> 0
C16: Total | E16: =SUM(E7:E15) -> 7551 | F16: =SUM(F7:F15) -> 0 | G16: =SUM(G7:G15) -> -7551 | I16: =SUM(I7:I15) -> 0 | J16: =SUM(J7:J15) -> 0 | K16: =SUM(K7:K15) -> 0 | L16: =SUM(L7:L15) -> 0 | M16: =SUM(M7:M15) -> 0 | N16: =SUM(N7:N15) -> 0 | O16: =SUM(O7:O15) -> 0 | P16: =SUM(P7:P15) -> 0
A18: Investimentos Insira aqui o montante mensal que você destinará aos seus investimentos | C18: Descrição | D18: Percentual | E18: Orçado | F18: Realizado | G18: Variação | I18: =I6 -> Semana 1 | J18: =J6 -> Semana 2 | K18: =K6 -> Semana 3 | L18: =L6 -> Semana 4 | M18: =M6 -> Semana 5 | P18: =P6 -> Total
C19: ='Orçamento Familiar'!C19 -> Reserva de Emergência (CP) R$ 9.151 | E19: ='Orçamento Familiar'!I19 -> 0 | F19: =P19 -> 0 | G19: =F19-E19 -> 0 | P19: =SUM(I19:O19) -> 0
C20: ='Orçamento Familiar'!C20 -> Projeto 1 | E20: ='Orçamento Familiar'!I20 -> 0 | F20: =P20 -> 0 | G20: =F20-E20 -> 0 | P20: =SUM(I20:O20) -> 0
C21: ='Orçamento Familiar'!C21 -> Projeto 2 | E21: ='Orçamento Familiar'!I21 -> 0 | F21: =P21 -> 0 | G21: =F21-E21 -> 0 | P21: =SUM(I21:O21) -> 0
C22: ='Orçamento Familiar'!C22 -> Projeto 3 | E22: ='Orçamento Familiar'!I22 -> 0 | F22: =P22 -> 0 | G22: =F22-E22 -> 0 | P22: =SUM(I22:O22) -> 0
C23: ='Orçamento Familiar'!C23 -> Projeto 4 | E23: ='Orçamento Familiar'!I23 -> 0 | F23: =P23 -> 0 | G23: =F23-E23 -> 0 | P23: =SUM(I23:O23) -> 0
C24: ='Orçamento Familiar'!C24 -> Projeto 5 | E24: ='Orçamento Familiar'!I24 -> 0 | F24: =P24 -> 0 | G24: =F24-E24 -> 0 | P24: =SUM(I24:O24) -> 0
C25: ='Orçamento Familiar'!C25 -> Projeto 6 | E25: ='Orçamento Familiar'!I25 -> 0 | F25: =P25 -> 0 | G25: =F25-E25 -> 0 | P25: =SUM(I25:O25) -> 0
C26: ='Orçamento Familiar'!C26 -> Independência Financeira | E26: ='Orçamento Familiar'!I26 -> 0 | F26: =P26 -> 0 | G26: =F26-E26 -> 0 | P26: =SUM(I26:O26) -> 0
C27: Total Investimentos | D27: =SUM(D19:D26) -> 0 | E27: =SUM(E19:E26) -> 0 | F27: =SUM(F19:F26) -> 0 | G27: =SUM(G19:G26) -> 0 | I27: =SUM(I19:I26) -> 0 | J27: =SUM(J19:J26) -> 0 | K27: =SUM(K19:K26) -> 0 | L27: =SUM(L19:L26) -> 0 | M27: =SUM(M19:M26) -> 0 | N27: =SUM(N19:N26) -> 0 | O27: =SUM(O19:O26) -> 0 | P27: =SUM(P19:P26) -> 0
C28: % sobre Receita | E28: =E27/E16 -> 0 | F28: =F27/F16 -> #DIV/0! | I28: =I27/I16 -> #DIV/0! | J28: =J27/J16 -> #DIV/0! | K28: =K27/K16 -> #DIV/0! | L28: =L27/L16 -> #DIV/0! | M28: =M27/M16 -> #DIV/0! | N28: =N27/N16 -> #DIV/0! | O28: =O27/O16 -> #DIV/0! | P28: =P27/P16 -> #DIV/0!
A30: Categoria | C30: Descrição | D30: Percentual | E30: Orçado | F30: Realizado | G30: Variação | I30: =I18 -> Semana 1 | J30: =J18 -> Semana 2 | K30: =K18 -> Semana 3 | L30: =L18 -> Semana 4 | M30: =M18 -> Semana 5 | N30: =N6 -> Cartão Nubank | O30: =O6 -> Cartão C & A | P30: =P18 -> Total
A31: Despesas Essenciais | B31: Moradia | C31: ='Orçamento Familiar'!C31 -> Aluguel | E31: ='Orçamento Familiar'!I31 -> 0 | F31: =P31 -> 0 | G31: =E31-F31 -> 0 | P31: =SUM(I31:O31) -> 0
C32: ='Orçamento Familiar'!C32 -> Energia Elétrica | E32: ='Orçamento Familiar'!I32 -> 0 | F32: =P32 -> 0 | G32: =E32-F32 -> 0 | P32: =SUM(I32:O32) -> 0
C33: ='Orçamento Familiar'!C33 -> Água e Esgoto | E33: ='Orçamento Familiar'!I33 -> 0 | F33: =P33 -> 0 | G33: =E33-F33 -> 0 | P33: =SUM(I33:O33) -> 0
C34: ='Orçamento Familiar'!C34 -> Gás | E34: ='Orçamento Familiar'!I34 -> 0 | F34: =P34 -> 0 | G34: =E34-F34 -> 0 | P34: =SUM(I34:O34) -> 0
C35: ='Orçamento Familiar'!C35 -> Internet e Celular | E35: ='Orçamento Familiar'!I35 -> 184.7 | F35: =P35 -> 0 | G35: =E35-F35 -> 184.7 | P35: =SUM(I35:O35) -> 0
C36: ='Orçamento Familiar'!C36 -> Manutenção | E36: ='Orçamento Familiar'!I36 -> 50 | F36: =P36 -> 0 | G36: =E36-F36 -> 50 | P36: =SUM(I36:O36) -> 0
C37: ='Orçamento Familiar'!C37 -> 0 | E37: ='Orçamento Familiar'!I37 -> 0 | F37: =P37 -> 0 | G37: =E37-F37 -> 0 | P37: =SUM(I37:O37) -> 0
C38: ='Orçamento Familiar'!C38 -> 0 | E38: ='Orçamento Familiar'!I38 -> 0 | F38: =P38 -> 0 | G38: =E38-F38 -> 0 | P38: =SUM(I38:O38) -> 0
C39: ='Orçamento Familiar'!C39 -> 0 | E39: ='Orçamento Familiar'!I39 -> 0 | F39: =P39 -> 0 | G39: =E39-F39 -> 0 | P39: =SUM(I39:O39) -> 0
B40: Alimentação | C40: ='Orçamento Familiar'!C40 -> Supermercado | E40: ='Orçamento Familiar'!I40 -> 3100 | F40: =P40 -> 0 | G40: =E40-F40 -> 3100 | P40: =SUM(I40:O40) -> 0
C41: ='Orçamento Familiar'!C41 -> 0 | E41: ='Orçamento Familiar'!I41 -> 0 | F41: =P41 -> 0 | G41: =E41-F41 -> 0 | P41: =SUM(I41:O41) -> 0
C42: ='Orçamento Familiar'!C42 -> 0 | E42: ='Orçamento Familiar'!I42 -> 0 | F42: =P42 -> 0 | G42: =E42-F42 -> 0 | P42: =SUM(I42:O42) -> 0
C43: ='Orçamento Familiar'!C43 -> 0 | E43: ='Orçamento Familiar'!I43 -> 0 | F43: =P43 -> 0 | G43: =E43-F43 -> 0 | P43: =SUM(I43:O43) -> 0
C44: ='Orçamento Familiar'!C44 -> 0 | E44: ='Orçamento Familiar'!I44 -> 0 | F44: =P44 -> 0 | G44: =E44-F44 -> 0 | P44: =SUM(I44:O44) -> 0
C45: ='Orçamento Familiar'!C45 -> 0 | E45: ='Orçamento Familiar'!I45 -> 0 | F45: =P45 -> 0 | G45: =E45-F45 -> 0 | P45: =SUM(I45:O45) -> 0
...

Sheet Jun
A2: Fluxo de Caixa Familiar
A5: Categoria | C5: Descrição | D5: Percentual | E5: =I5 -> Junho | I5: Junho
E6: Orçado | F6: Realizado | G6: Variação | I6: Semana 1 | J6: Semana 2 | K6: Semana 3 | L6: Semana 4 | M6: Semana 5 | N6: =Jan!N6 -> Cartão Nubank | O6: =Jan!O6 -> Cartão C & A | P6: Total
A7: Receitas | C7: ='Orçamento Familiar'!C7 -> Prebenda | E7: ='Orçamento Familiar'!J7 -> 7216 | F7: =P7 -> 0 | G7: =F7-E7 -> -7216 | P7: =SUM(I7:O7) -> 0
C8: ='Orçamento Familiar'!C8 -> Inglês | E8: ='Orçamento Familiar'!J8 -> 335 | F8: =P8 -> 0 | G8: =F8-E8 -> -335 | P8: =SUM(I8:O8) -> 0
C9: ='Orçamento Familiar'!C9 -> 13º Salário | E9: ='Orçamento Familiar'!J9 -> 0 | F9: =P9 -> 0 | G9: =F9-E9 -> 0 | P9: =SUM(I9:O9) -> 0
C10: ='Orçamento Familiar'!C10 -> Renda Extra | E10: ='Orçamento Familiar'!J10 -> 0 | F10: =P10 -> 0 | G10: =F10-E10 -> 0 | P10: =SUM(I10:O10) -> 0
C11: ='Orçamento Familiar'!C11 -> 0 | E11: ='Orçamento Familiar'!J11 -> 0 | F11: =P11 -> 0 | G11: =F11-E11 -> 0 | P11: =SUM(I11:O11) -> 0
C12: ='Orçamento Familiar'!C12 -> 0 | E12: ='Orçamento Familiar'!J12 -> 0 | F12: =P12 -> 0 | G12: =F12-E12 -> 0 | P12: =SUM(I12:O12) -> 0
C13: ='Orçamento Familiar'!C13 -> 0 | E13: ='Orçamento Familiar'!J13 -> 0 | F13: =P13 -> 0 | G13: =F13-E13 -> 0 | P13: =SUM(I13:O13) -> 0
C14: ='Orçamento Familiar'!C14 -> 0 | E14: ='Orçamento Familiar'!J14 -> 0 | F14: =P14 -> 0 | G14: =F14-E14 -> 0 | P14: =SUM(I14:O14) -> 0
C15: ='Orçamento Familiar'!C15 -> 0 | E15: ='Orçamento Familiar'!J15 -> 0 | F15: =P15 -> 0 | G15: =F15-E15 -> 0 | P15: =SUM(I15:O15) -> 0
C16: Total | E16: =SUM(E7:E15) -> 7551 | F16: =SUM(F7:F15) -> 0 | G16: =SUM(G7:G15) -> -7551 | I16: =SUM(I7:I15) -> 0 | J16: =SUM(J7:J15) -> 0 | K16: =SUM(K7:K15) -> 0 | L16: =SUM(L7:L15) -> 0 | M16: =SUM(M7:M15) -> 0 | N16: =SUM(N7:N15) -> 0 | O16: =SUM(O7:O15) -> 0 | P16: =SUM(P7:P15) -> 0
A18: Investimentos Insira aqui o montante mensal que você destinará aos seus investimentos | C18: Descrição | D18: Percentual | E18: Orçado | F18: Realizado | G18: Variação | I18: =I6 -> Semana 1 | J18: =J6 -> Semana 2 | K18: =K6 -> Semana 3 | L18: =L6 -> Semana 4 | M18: =M6 -> Semana 5 | P18: =P6 -> Total
